Workbook

Sheet Price Calculator
A3: Choose Hearing Aid Model | B3: Beltone RIE Digital XF 9 60SDRWC
A5: Choose Qty | B5: 2
A7: Discount Code | B7: BCBS Blue365 Member
A10: If you get an #N/A error, it means that hearing aid chosen is not available for that discount program.
A12: HEARING AID 1 | B12: Pricing | C12: HEARING AID 2 | D12: Pricing
A13: MSRP each | B13: {=IF($B$3="","",_xlfn.XLOOKUP($B$3&$B$7,haList!A:A&haList!I:I,haList!D:D))} -> 5579 | C13: MSRP each | D13: {=IF($B$5=1,"",_xlfn.XLOOKUP($B$3&$B$7,haList!A:A&haList!I:I,haList!D:D))} -> 5579
A14: Volume Discount | B14: {=_xlfn.XLOOKUP($B$3,haList!$A:$A,-haList!$F:$F)} -> 162.5 | C14: Volume Discount | D14: {=IF(B5=1,"",_xlfn.XLOOKUP($B$3,haList!$A:$A,-haList!$F:$F))} -> 162.5
A15: List Price | B15: =B13+B14 -> 5741.5 | C15: List Price | D15: =IF(B5=1,"",D13+D14) -> 5741.5
A16: Discount 2 | B16: {=_xlfn.XLOOKUP($B$3&$B$7,haList!$A:$A&haList!$I:$I,-haList!$J:$J)} -> -3405 | C16: Discount 2 | D16: {=IF(B5=1,"",_xlfn.XLOOKUP($B$3&$B$7,haList!$A:$A&haList!$I:$I,-haList!$J:$J))} -> -3405
A17: Net Price | B17: =B15+B16 -> 2336.5 | C17: Net Price | D17: =IF(B5=1,"",D15+D16) -> 2336.5
A18: Discount 3 | B18: {=IF($B$7="Open House Special",_xlfn.XLOOKUP($B$3&"Marketing Offer",haList!$A:$A&haList!$M:$M,-haList!$N:$N),0)} -> 0 | C18: Discount 3 | D18: {=IF(B5=1,"",IF($B$7="Open House Special",_xlfn.XLOOKUP($B$3&"Marketing Offer",haList!$A:$A&haList!$M:$M,-haList!$N:$N),0))} -> 0
A19: Final Price | B19: =B17+B18 -> 2336.5 | C19: Final Price | D19: =IF(B5=1,"",D17+D18) -> 2336.5
B22: Hearing Aid 1 | C22: =B19 -> 2336.5
B23: =IF($B$5=1,"",B22) -> Hearing Aid 1 | C23: =IF(B5=2,D19,0) -> 2336.5
B24: {=IF($B$3="","",_xlfn.XLOOKUP($B$3&$B$7,haList!$A:$A&haList!$I:$I,haList!$R:$R))} -> Standard Charger | C24: {=IF($B$24="","",_xlfn.XLOOKUP($B$3&$B$7,haList!$A:$A&haList!$I:$I,haList!$S:$S))} -> 325
B25: {=IF($B$3="","",_xlfn.XLOOKUP($B$3&$B$7,haList!$A:$A&haList!$I:$I,haList!$T:$T))} -> SureFit3 or M@RIE Receiver | C25: {=IF($B$24="","",_xlfn.XLOOKUP($B$3&$B$7,haList!$A:$A&haList!$I:$I,haList!$U:$U))} -> 0
B26: =IF($B$5=1,"",B25) -> SureFit3 or M@RIE Receiver | C26: =IF(B5=2,C25,0) -> 0
B27: SubTotal | C27: =C22+C23+C24+C25+C26 -> 4998
B28: {=IF($B$3="","",IF(_xlfn.XLOOKUP($B$3&$B$7,haList!$A:$A&haList!$I:$I,haList!$Q:$Q)=1,"PA Fitting Fee","(do not charge a PA Fitting Fee)"))} -> PA Fitting Fee | C28: {=IF($B$3="","",IF(_xlfn.XLOOKUP($B$3&$B$7,haList!$A:$A&haList!$I:$I,haList!$Q:$Q)=1,400,""))} -> 400 | G28: =IF(B7="Anthem BCBS","<---Needs to be on a separate invoice. Private Pay only!","")
B29: TOTAL | C29: =C27+C28 -> 5398
B32: Choose how the patient is planning on paying
B33: AllWell Fast Funding | C33: =C29 -> 5398
B34: =IF($B$33='Data Lists'!C3,"Down Payment Type is Needed",IF($B$33='Data Lists'!C4,"20% down payment needed",IF($B$33='Data Lists'!C5,"20% down payment needed",IF($B$33='Data Lists'!C6,"$800 down payment needed",IF(AND($B$33='Data Lists'!C7,F29>5555),"Down Payment Needed",IF(AND($B$33='Data Lists'!C7,F29<5555),"10% Down Payment Needed")))))) -> 10% Down Payment Needed | C34: =IF(B33='Data Lists'!C3,0, IF(B33='Data Lists'!C4,'Price Calculator'!C33*20%, IF(B33='Data Lists'!C5,'Price Calculator'!C33*20%, IF('Price Calculator'!B33='Data Lists'!C6,800, IF(AND('Price Calculator'!B33='Data Lists'!C7,C33<5555),C33*10%, IF(AND('Price Calculator'!B33='Data Lists'!C7,C33>5555),C33-5000,"")))))) -> 539.8
B35: =IF($B$33='Data Lists'!C3,"Down Payment Type is Needed",IF($B$33='Data Lists'!C4,"Balance due from Patient at delivery",IF(OR($B$33='Data Lists'!C5,$B$33='Data Lists'!C6,$B$33='Data Lists'!C7),"Balance due from AllWell at delivery"))) -> Balance due from AllWell at delivery | C35: =C33-C34 -> 4858.2

Sheet haList
A1: haModel | B1: haDescription | C1: BiNuralMSRP w/Charger | D1: haMSRP | E1: Discount Type 1 | F1: Discount Amount 1 | G1: HAListPrice | H1: ListPriceBinural | I1: Discount Type 2 | J1: Discount Amount 2 | K1: haNetPrice | L1: haNetPriceBinural | M1: Discount Type 3 | N1: Discount Amount 3 | O1: haNetPrice2 | P1: haNetPriceBinural2 | Q1: paFittingFee | R1: chargerType | S1: chargerPrice | T1: haReceiverType | U1: haReceiverPrice | V1: haReceiverDiscountDescription
A2: Beltone BTE Digital Boost Max S 17 95-DWHC | B2: Beltone Boost Max S 17 95-DWHC Digital BTE | C2: =(HearingAids7[[#This Row],[haMSRP]]*2)+HearingAids7[[#This Row],[chargerPrice]] -> 12103 | D2: 5939 | E2: Volume Discount | F2: =HearingAids7[[#This Row],[haMSRP]]-((HearingAids7[[#This Row],[ListPriceBinural]]-HearingAids7[[#This Row],[chargerPrice]])/2) -> 1226.5 | G2: =HearingAids7[[#This Row],[haMSRP]]-HearingAids7[[#This Row],[Discount Amount 1]] -> 4712.5 | H2: 9650 | I2: Marketing Offer | J2: =(HearingAids7[[#This Row],[haMSRP]]-HearingAids7[[#This Row],[Discount Amount 1]])-(HearingAids7[[#This Row],[haNetPriceBinural]]-HearingAids7[[#This Row],[chargerPrice]])/2 -> 500 | K2: =HearingAids7[[#This Row],[HAListPrice]]-HearingAids7[[#This Row],[Discount Amount 2]] -> 4212.5 | L2: 8650 | Q2: 1 | R2: Desktop Charger | S2: 225 | T2: SureFit3 or M@RIE Receiver | U2: 0 | V2: 100% Discount
A3: Beltone BTE Digital Boost Max S 17 95-DWHC | B3: Beltone Boost Max S 17 95-DWHC Digital BTE | C3: =(HearingAids7[[#This Row],[haMSRP]]*2)+HearingAids7[[#This Row],[chargerPrice]] -> 12103 | D3: 5939 | E3: Volume Discount | F3: =HearingAids7[[#This Row],[haMSRP]]-((HearingAids7[[#This Row],[ListPriceBinural]]-HearingAids7[[#This Row],[chargerPrice]])/2) -> 1226.5 | G3: =HearingAids7[[#This Row],[haMSRP]]-HearingAids7[[#This Row],[Discount Amount 1]] -> 4712.5 | H3: 9650 | I3: Open House Special | J3: =((HearingAids7[[#This Row],[haMSRP]]-HearingAids7[[#This Row],[Discount Amount 1]])-(HearingAids7[[#This Row],[haNetPriceBinural]]-HearingAids7[[#This Row],[chargerPrice]])/2) -> 1025 | K3: =HearingAids7[[#This Row],[HAListPrice]]-HearingAids7[[#This Row],[Discount Amount 2]] -> 3687.5 | L3: 7600 | Q3: 1 | R3: Desktop Charger | S3: 225 | T3: SureFit3 or M@RIE Receiver | U3: 0 | V3: 100% Discount
A4: Beltone BTE Digital Boost Max S 4 95-DWHC | B4: Beltone Boost Max S 4 95-DWHC Digital BTE | C4: =(HearingAids7[[#This Row],[haMSRP]]*2)+HearingAids7[[#This Row],[chargerPrice]] -> 6523 | D4: 3149 | E4: Volume Discount | F4: =HearingAids7[[#This Row],[haMSRP]]-((HearingAids7[[#This Row],[ListPriceBinural]]-HearingAids7[[#This Row],[chargerPrice]])/2) -> 586.5 | G4: =HearingAids7[[#This Row],[haMSRP]]-HearingAids7[[#This Row],[Discount Amount 1]] -> 2562.5 | H4: 5350 | I4: <none> | J4: =(HearingAids7[[#This Row],[haMSRP]]-HearingAids7[[#This Row],[Discount Amount 1]])-(HearingAids7[[#This Row],[haNetPriceBinural]]-HearingAids7[[#This Row],[chargerPrice]])/2 -> 0 | K4: =HearingAids7[[#This Row],[HAListPrice]]-HearingAids7[[#This Row],[Discount Amount 2]] -> 2562.5 | L4: =HearingAids7[[#This Row],[ListPriceBinural]] -> 5350 | Q4: 1 | R4: Desktop Charger | S4: 225
A5: Beltone BTE Digital Boost Max S 6 95-DWHC | B5: Beltone Boost Max S 6 95-DWHC Digital BTE | C5: =(HearingAids7[[#This Row],[haMSRP]]*2)+HearingAids7[[#This Row],[chargerPrice]] -> 7903 | D5: 3839 | E5: Volume Discount | F5: =HearingAids7[[#This Row],[haMSRP]]-((HearingAids7[[#This Row],[ListPriceBinural]]-HearingAids7[[#This Row],[chargerPrice]])/2) -> 226.5 | G5: =HearingAids7[[#This Row],[haMSRP]]-HearingAids7[[#This Row],[Discount Amount 1]] -> 3612.5 | H5: 7450 | I5: Marketing Offer | J5: =(HearingAids7[[#This Row],[haMSRP]]-HearingAids7[[#This Row],[Discount Amount 1]])-(HearingAids7[[#This Row],[haNetPriceBinural]]-HearingAids7[[#This Row],[chargerPrice]])/2 -> 500 | K5: =HearingAids7[[#This Row],[HAListPrice]]-HearingAids7[[#This Row],[Discount Amount 2]] -> 3112.5 | L5: =HearingAids7[[#This Row],[ListPriceBinural]]-1000 -> 6450 | Q5: 1 | R5: Desktop Charger | S5: 225 | T5: SureFit3 or M@RIE Receiver | U5: 0 | V5: 100% Discount
A6: Beltone BTE Digital Boost Max S 6 95-DWHC | B6: Beltone Boost Max S 6 95-DWHC Digital BTE | C6: =(HearingAids7[[#This Row],[haMSRP]]*2)+HearingAids7[[#This Row],[chargerPrice]] -> 7903 | D6: 3839 | E6: Volume Discount | F6: =HearingAids7[[#This Row],[haMSRP]]-((HearingAids7[[#This Row],[ListPriceBinural]]-HearingAids7[[#This Row],[chargerPrice]])/2) -> 226.5 | G6: =HearingAids7[[#This Row],[haMSRP]]-HearingAids7[[#This Row],[Discount Amount 1]] -> 3612.5 | H6: 7450 | I6: Open House Special | J6: =((HearingAids7[[#This Row],[haMSRP]]-HearingAids7[[#This Row],[Discount Amount 1]])-(HearingAids7[[#This Row],[haNetPriceBinural]]-HearingAids7[[#This Row],[chargerPrice]])/2) -> 525 | K6: =HearingAids7[[#This Row],[HAListPrice]]-HearingAids7[[#This Row],[Discount Amount 2]] -> 3087.5 | L6: 6400 | Q6: 1 | R6: Desktop Charger | S6: 225 | T6: SureFit3 or M@RIE Receiver | U6: 0 | V6: 100% Discount
A7: Beltone BTE Digital Boost Max S 9 95-DWHC | B7: Beltone Boost Max S 9 95-DWHC Digital BTE | C7: =(HearingAids7[[#This Row],[haMSRP]]*2)+HearingAids7[[#This Row],[chargerPrice]] -> 10303 | D7: 5039 | E7: Volume Discount | F7: =HearingAids7[[#This Row],[haMSRP]]-((HearingAids7[[#This Row],[ListPriceBinural]]-HearingAids7[[#This Row],[chargerPrice]])/2) -> 876.5 | G7: =HearingAids7[[#This Row],[haMSRP]]-HearingAids7[[#This Row],[Discount Amount 1]] -> 4162.5 | H7: 8550 | I7: Marketing Offer | J7: =(HearingAids7[[#This Row],[haMSRP]]-HearingAids7[[#This Row],[Discount Amount 1]])-(HearingAids7[[#This Row],[haNetPriceBinural]]-HearingAids7[[#This Row],[chargerPrice]])/2 -> 500 | K7: =HearingAids7[[#This Row],[HAListPrice]]-HearingAids7[[#This Row],[Discount Amount 2]] -> 3662.5 | L7: =HearingAids7[[#This Row],[ListPriceBinural]]-1000 -> 7550 | Q7: 1 | R7: Desktop Charger | S7: 225 | T7: SureFit3 or M@RIE Receiver | U7: 0 | V7: 100% Discount
A8: Beltone BTE Digital Boost Max S 9 95-DWHC | B8: Beltone Boost Max S 9 95-DWHC Digital BTE | C8: =(HearingAids7[[#This Row],[haMSRP]]*2)+HearingAids7[[#This Row],[chargerPrice]] -> 10303 | D8: 5039 | E8: Volume Discount | F8: =HearingAids7[[#This Row],[haMSRP]]-((HearingAids7[[#This Row],[ListPriceBinural]]-HearingAids7[[#This Row],[chargerPrice]])/2) -> 876.5 | G8: =HearingAids7[[#This Row],[haMSRP]]-HearingAids7[[#This Row],[Discount Amount 1]] -> 4162.5 | H8: 8550 | I8: Open House Special | J8: =((HearingAids7[[#This Row],[haMSRP]]-HearingAids7[[#This Row],[Discount Amount 1]])-(HearingAids7[[#This Row],[haNetPriceBinural]]-HearingAids7[[#This Row],[chargerPrice]])/2) -> 625 | K8: =HearingAids7[[#This Row],[HAListPrice]]-HearingAids7[[#This Row],[Discount Amount 2]] -> 3537.5 | L8: 7300 | Q8: 1 | R8: Desktop Charger | S8: 225 | T8: SureFit3 or M@RIE Receiver | U8: 0 | V8: 100% Discount
A9: Beltone RIE Digital Commence 2 63-DRW | B9: Beltone Commence 2 63-DRW Digital RIE | C9: =(HearingAids7[[#This Row],[haMSRP]]*2)+HearingAids7[[#This Row],[chargerPrice]] -> 3898 | D9: 1949 | E9: Volume Discount | F9: =HearingAids7[[#This Row],[haMSRP]]-((HearingAids7[[#This Row],[ListPriceBinural]]-HearingAids7[[#This Row],[chargerPrice]])/2) -> 399 | G9: =HearingAids7[[#This Row],[haMSRP]]-HearingAids7[[#This Row],[Discount Amount 1]] -> 1550 | H9: 3100 | I9: <none> | J9: 0 | K9: =HearingAids7[[#This Row],[HAListPrice]]-HearingAids7[[#This Row],[Discount Amount 2]] -> 1550 | Q9: 1 | R9: None | S9: 0
A10: Beltone RIE Digital Commence 2 63-DRW | B10: Beltone Commence 2 63-DRW Digital RIE | C10: =(HearingAids7[[#This Row],[haMSRP]]*2)+HearingAids7[[#This Row],[chargerPrice]] -> 3898 | D10: 1949 | E10: Volume Discount | F10: =HearingAids7[[#This Row],[haMSRP]]-((HearingAids7[[#This Row],[ListPriceBinural]]-HearingAids7[[#This Row],[chargerPrice]])/2) -> 399 | G10: =HearingAids7[[#This Row],[haMSRP]]-HearingAids7[[#This Row],[Discount Amount 1]] -> 1550 | H10: 3100 | I10: Fast Funding | J10: =(HearingAids7[[#This Row],[haMSRP]]-HearingAids7[[#This Row],[Discount Amount 1]])-(HearingAids7[[#This Row],[haNetPriceBinural]]-HearingAids7[[#This Row],[chargerPrice]])/2 -> 0 | K10: =HearingAids7[[#This Row],[HAListPrice]]-HearingAids7[[#This Row],[Discount Amount 2]] -> 1550 | L10: 3100 | Q10: 1 | R10: None | S10: 0 | T10: SureFit3 or M@RIE Receiver | U10: 0 | V10: 100% Discount
A11: Beltone RIE Digital Commence 3 62-DRWC | B11: Beltone Commence 3 62-DRWC Digital RIE | C11: =(HearingAids7[[#This Row],[haMSRP]]*2)+HearingAids7[[#This Row],[chargerPrice]] -> 5143 | D11: 2459 | E11: Volume Discount | F11: =HearingAids7[[#This Row],[haMSRP]]-((HearingAids7[[#This Row],[ListPriceBinural]]-HearingAids7[[#This Row],[chargerPrice]])/2) -> 576.5 | G11: =HearingAids7[[#This Row],[haMSRP]]-HearingAids7[[#This Row],[Discount Amount 1]] -> 1882.5 | H11: 3990 | I11: Amplifon Competitive | J11: =(HearingAids7[[#This Row],[haMSRP]]-HearingAids7[[#This Row],[Discount Amount 1]])-(HearingAids7[[#This Row],[haNetPriceBinural]]-HearingAids7[[#This Row],[chargerPrice]])/2 -> 300 | K11: =HearingAids7[[#This Row],[HAListPrice]]-HearingAids7[[#This Row],[Discount Amount 2]] -> 1582.5 | L11: 3390 | Q11: 1 | R11: Desktop Charger | S11: 225 | T11: SureFit | U11: 0 | V11: 100% Discount
A12: Beltone RIE Digital Commence 3 62-DRWC | B12: Beltone Commence 3 62-DRWC Digital RIE | C12: =(HearingAids7[[#This Row],[haMSRP]]*2)+HearingAids7[[#This Row],[chargerPrice]] -> 5143 | D12: 2459 | E12: Volume Discount | F12: =HearingAids7[[#This Row],[haMSRP]]-((HearingAids7[[#This Row],[ListPriceBinural]]-HearingAids7[[#This Row],[chargerPrice]])/2) -> 576.5 | G12: =HearingAids7[[#This Row],[haMSRP]]-HearingAids7[[#This Row],[Discount Amount 1]] -> 1882.5 | H12: 3990 | I12: <none> | J12: 0 | K12: =HearingAids7[[#This Row],[HAListPrice]]-HearingAids7[[#This Row],[Discount Amount 2]] -> 1882.5 | L12: 3990 | Q12: 1 | R12: Desktop Charger | S12: 225 | T12: SureFit | U12: 0 | V12: 100% Discount
A13: Beltone RIE Digital Commence 3 62-DRWC | B13: Beltone Commence 3 62-DRWC Digital RIE | C13: =(HearingAids7[[#This Row],[haMSRP]]*2)+HearingAids7[[#This Row],[chargerPrice]] -> 5143 | D13: 2459 | E13: Volume Discount | F13: =HearingAids7[[#This Row],[haMSRP]]-((HearingAids7[[#This Row],[ListPriceBinural]]-HearingAids7[[#This Row],[chargerPrice]])/2) -> 576.5 | G13: =HearingAids7[[#This Row],[haMSRP]]-HearingAids7[[#This Row],[Discount Amount 1]] -> 1882.5 | H13: 3990 | I13: Humana | J13: =(HearingAids7[[#This Row],[haMSRP]]-HearingAids7[[#This Row],[Discount Amount 1]])-(HearingAids7[[#This Row],[haNetPriceBinural]]-HearingAids7[[#This Row],[chargerPrice]])/2 -> 300 | K13: =HearingAids7[[#This Row],[HAListPrice]]-HearingAids7[[#This Row],[Discount Amount 2]] -> 1582.5 | L13: 3390 | Q13: 1 | R13: Desktop Charger | S13: 225 | T13: SureFit | U13: 0 | V13: 100% Discount
A14: Beltone RIE Digital Commence 3 62-DRWC | B14: Beltone Commence 3 62-DRWC Digital RIE | C14: =(HearingAids7[[#This Row],[haMSRP]]*2)+HearingAids7[[#This Row],[chargerPrice]] -> 5143 | D14: 2459 | E14: Volume Discount | F14: =HearingAids7[[#This Row],[haMSRP]]-((HearingAids7[[#This Row],[ListPriceBinural]]-HearingAids7[[#This Row],[chargerPrice]])/2) -> 576.5 | G14: =HearingAids7[[#This Row],[haMSRP]]-HearingAids7[[#This Row],[Discount Amount 1]] -> 1882.5 | H14: 3990 | I14: GHB/BCBS Competitive | J14: =(HearingAids7[[#This Row],[haMSRP]]-HearingAids7[[#This Row],[Discount Amount 1]])-(HearingAids7[[#This Row],[haNetPriceBinural]]-HearingAids7[[#This Row],[chargerPrice]])/2 -> 300 | K14: =HearingAids7[[#This Row],[HAListPrice]]-HearingAids7[[#This Row],[Discount Amount 2]] -> 1582.5 | L14: 3390 | Q14: 1 | R14: Desktop Charger | S14: 225 | T14: SureFit | U14: 0 | V14: 100% Discount
A15: Beltone RIE Digital Commence 3 62-DRWC | B15: Beltone Commence 3 62-DRWC Digital RIE | C15: =(HearingAids7[[#This Row],[haMSRP]]*2)+HearingAids7[[#This Row],[chargerPrice]] -> 5143 | D15: 2459 | E15: Volume Discount | F15: =HearingAids7[[#This Row],[haMSRP]]-((HearingAids7[[#This Row],[ListPriceBinural]]-HearingAids7[[#This Row],[chargerPrice]])/2) -> 576.5 | G15: =HearingAids7[[#This Row],[haMSRP]]-HearingAids7[[#This Row],[Discount Amount 1]] -> 1882.5 | H15: 3990 | I15: HCS Competitive | J15: =(HearingAids7[[#This Row],[haMSRP]]-HearingAids7[[#This Row],[Discount Amount 1]])-(HearingAids7[[#This Row],[haNetPriceBinural]]-HearingAids7[[#This Row],[chargerPrice]])/2 -> 300 | K15: =HearingAids7[[#This Row],[HAListPrice]]-HearingAids7[[#This Row],[Discount Amount 2]] -> 1582.5 | L15: 3390 | Q15: 1 | R15: Desktop Charger | S15: 225 | T15: SureFit | U15: 0 | V15: 100% Discount
A16: Beltone RIE Digital Commence 3 62-DRWC | B16: Beltone Commence 3 62-DRWC Digital RIE | C16: =(HearingAids7[[#This Row],[haMSRP]]*2)+HearingAids7[[#This Row],[chargerPrice]] -> 5143 | D16: 2459 | E16: Volume Discount | F16: =HearingAids7[[#This Row],[haMSRP]]-((HearingAids7[[#This Row],[ListPriceBinural]]-HearingAids7[[#This Row],[chargerPrice]])/2) -> 576.5 | G16: =HearingAids7[[#This Row],[haMSRP]]-HearingAids7[[#This Row],[Discount Amount 1]] -> 1882.5 | H16: 3990 | I16: HearUSA Competitive | J16: =(HearingAids7[[#This Row],[haMSRP]]-HearingAids7[[#This Row],[Discount Amount 1]])-(HearingAids7[[#This Row],[haNetPriceBinural]]-HearingAids7[[#This Row],[chargerPrice]])/2 -> 300 | K16: =HearingAids7[[#This Row],[HAListPrice]]-HearingAids7[[#This Row],[Discount Amount 2]] -> 1582.5 | L16: 3390 | Q16: 1 | R16: Desktop Charger | S16: 225 | T16: SureFit | U16: 0 | V16: 100% Discount
A17: Beltone RIE Digital Commence 3 62-DRWC | B17: Beltone Commence 3 62-DRWC Digital RIE | C17: =(HearingAids7[[#This Row],[haMSRP]]*2)+HearingAids7[[#This Row],[chargerPrice]] -> 5143 | D17: 2459 | E17: Volume Discount | F17: =HearingAids7[[#This Row],[haMSRP]]-((HearingAids7[[#This Row],[ListPriceBinural]]-HearingAids7[[#This Row],[chargerPrice]])/2) -> 576.5 | G17: =HearingAids7[[#This Row],[haMSRP]]-HearingAids7[[#This Row],[Discount Amount 1]] -> 1882.5 | H17: 3990 | I17: Martins Point Competitive | J17: =(HearingAids7[[#This Row],[haMSRP]]-HearingAids7[[#This Row],[Discount Amount 1]])-(HearingAids7[[#This Row],[haNetPriceBinural]]-HearingAids7[[#This Row],[chargerPrice]])/2 -> 300 | K17: =HearingAids7[[#This Row],[HAListPrice]]-HearingAids7[[#This Row],[Discount Amount 2]] -> 1582.5 | L17: 3390 | Q17: 1 | R17: Desktop Charger | S17: 225 | T17: SureFit | U17: 0 | V17: 100% Discount
A18: Beltone RIE Digital Commence 3 62-DRWC | B18: Beltone Commence 3 62-DRWC Digital RIE | C18: =(HearingAids7[[#This Row],[haMSRP]]*2)+HearingAids7[[#This Row],[chargerPrice]] -> 5143 | D18: 2459 | E18: Volume Discount | F18: =HearingAids7[[#This Row],[haMSRP]]-((HearingAids7[[#This Row],[ListPriceBinural]]-HearingAids7[[#This Row],[chargerPrice]])/2) -> 576.5 | G18: =HearingAids7[[#This Row],[haMSRP]]-HearingAids7[[#This Row],[Discount Amount 1]] -> 1882.5 | H18: 3990 | I18: Nations Hearing Competitive | J18: =(HearingAids7[[#This Row],[haMSRP]]-HearingAids7[[#This Row],[Discount Amount 1]])-(HearingAids7[[#This Row],[haNetPriceBinural]]-HearingAids7[[#This Row],[chargerPrice]])/2 -> 300 | K18: =HearingAids7[[#This Row],[HAListPrice]]-HearingAids7[[#This Row],[Discount Amount 2]] -> 1582.5 | L18: 3390 | Q18: 1 | R18: Desktop Charger | S18: 225 | T18: SureFit | U18: 0 | V18: 100% Discount
A19: Beltone RIE Digital Commence 3 62-DRWC | B19: Beltone Commence 3 62-DRWC Digital RIE | C19: =(HearingAids7[[#This Row],[haMSRP]]*2)+HearingAids7[[#This Row],[chargerPrice]] -> 5143 | D19: 2459 | E19: Volume Discount | F19: =HearingAids7[[#This Row],[haMSRP]]-((HearingAids7[[#This Row],[ListPriceBinural]]-HearingAids7[[#This Row],[chargerPrice]])/2) -> 576.5 | G19: =HearingAids7[[#This Row],[haMSRP]]-HearingAids7[[#This Row],[Discount Amount 1]] -> 1882.5 | H19: 3990 | I19: TruHearing Competitive | J19: =(HearingAids7[[#This Row],[haMSRP]]-HearingAids7[[#This Row],[Discount Amount 1]])-(HearingAids7[[#This Row],[haNetPriceBinural]]-HearingAids7[[#This Row],[chargerPrice]])/2 -> 300 | K19: =HearingAids7[[#This Row],[HAListPrice]]-HearingAids7[[#This Row],[Discount Amount 2]] -> 1582.5 | L19: 3390 | Q19: 1 | R19: Desktop Charger | S19: 225 | T19: SureFit | U19: 0 | V19: 100% Discount
A20: Beltone RIE Digital Commence 3 62-DRWC | B20: Beltone Commence 3 62-DRWC Digital RIE | C20: =(HearingAids7[[#This Row],[haMSRP]]*2)+HearingAids7[[#This Row],[chargerPrice]] -> 5143 | D20: 2459 | E20: Volume Discount | F20: =HearingAids7[[#This Row],[haMSRP]]-((HearingAids7[[#This Row],[ListPriceBinural]]-HearingAids7[[#This Row],[chargerPrice]])/2) -> 576.5 | G20: =HearingAids7[[#This Row],[haMSRP]]-HearingAids7[[#This Row],[Discount Amount 1]] -> 1882.5 | H20: 3990 | I20: Tri-Care | J20: =(HearingAids7[[#This Row],[haMSRP]]-HearingAids7[[#This Row],[Discount Amount 1]])-(HearingAids7[[#This Row],[haNetPriceBinural]]-HearingAids7[[#This Row],[chargerPrice]])/2 -> 300 | K20: =HearingAids7[[#This Row],[HAListPrice]]-HearingAids7[[#This Row],[Discount Amount 2]] -> 1582.5 | L20: 3390 | Q20: 1 | R20: Desktop Charger | S20: 225 | T20: SureFit | U20: 0 | V20: 100% Discount
A21: Beltone RIE Digital Commence 3 62-DRWC | B21: Beltone Commence 3 62-DRWC Digital RIE | C21: =(HearingAids7[[#This Row],[haMSRP]]*2)+HearingAids7[[#This Row],[chargerPrice]] -> 5143 | D21: 2459 | E21: Volume Discount | F21: =HearingAids7[[#This Row],[haMSRP]]-((HearingAids7[[#This Row],[ListPriceBinural]]-HearingAids7[[#This Row],[chargerPrice]])/2) -> 576.5 | G21: =HearingAids7[[#This Row],[haMSRP]]-HearingAids7[[#This Row],[Discount Amount 1]] -> 1882.5 | H21: 3990 | I21: UHCH Competitive | J21: =(HearingAids7[[#This Row],[haMSRP]]-HearingAids7[[#This Row],[Discount Amount 1]])-(HearingAids7[[#This Row],[haNetPriceBinural]]-HearingAids7[[#This Row],[chargerPrice]])/2 -> 300 | K21: =HearingAids7[[#This Row],[HAListPrice]]-HearingAids7[[#This Row],[Discount Amount 2]] -> 1582.5 | L21: 3390 | Q21: 1 | R21: Desktop Charger | S21: 225 | T21: SureFit | U21: 0 | V21: 100% Discount
A22: Beltone RIE Digital Commence 3 62-DRWC | B22: Beltone Commence 3 62-DRWC Digital RIE | C22: =(HearingAids7[[#This Row],[haMSRP]]*2)+HearingAids7[[#This Row],[chargerPrice]] -> 5143 | D22: 2459 | E22: Volume Discount | F22: =HearingAids7[[#This Row],[haMSRP]]-((HearingAids7[[#This Row],[ListPriceBinural]]-HearingAids7[[#This Row],[chargerPrice]])/2) -> 576.5 | G22: =HearingAids7[[#This Row],[haMSRP]]-HearingAids7[[#This Row],[Discount Amount 1]] -> 1882.5 | H22: 3990 | I22: Veterans Discount | J22: =(HearingAids7[[#This Row],[haMSRP]]-HearingAids7[[#This Row],[Discount Amount 1]])-(HearingAids7[[#This Row],[haNetPriceBinural]]-HearingAids7[[#This Row],[chargerPrice]])/2 -> 300 | K22: =HearingAids7[[#This Row],[HAListPrice]]-HearingAids7[[#This Row],[Discount Amount 2]] -> 1582.5 | L22: 3390 | Q22: 1 | R22: Desktop Charger | S22: 225 | T22: SureFit | U22: 0 | V22: 100% Discount
A23: Beltone RIE Digital Commence 3 62-DRWC | B23: Beltone Commence 3 62-DRWC Digital RIE | C23: =(HearingAids7[[#This Row],[haMSRP]]*2)+HearingAids7[[#This Row],[chargerPrice]] -> 5143 | D23: 2459 | E23: Volume Discount | F23: =HearingAids7[[#This Row],[haMSRP]]-((HearingAids7[[#This Row],[ListPriceBinural]]-HearingAids7[[#This Row],[chargerPrice]])/2) -> 576.5 | G23: =HearingAids7[[#This Row],[haMSRP]]-HearingAids7[[#This Row],[Discount Amount 1]] -> 1882.5 | H23: 3990 | I23: WellCare Competitive | J23: =(HearingAids7[[#This Row],[haMSRP]]-HearingAids7[[#This Row],[Discount Amount 1]])-(HearingAids7[[#This Row],[haNetPriceBinural]]-HearingAids7[[#This Row],[chargerPrice]])/2 -> 300 | K23: =HearingAids7[[#This Row],[HAListPrice]]-HearingAids7[[#This Row],[Discount Amount 2]] -> 1582.5 | L23: 3390 | Q23: 1 | R23: Desktop Charger | S23: 225 | T23: SureFit | U23: 0 | V23: 100% Discount
A24: Beltone RIE Digital Envision 17 62S-DRWC | B24: Beltone Envision 17 62S-DRWC Digital RIE | C24: =(HearingAids7[[#This Row],[haMSRP]]*2)+HearingAids7[[#This Row],[chargerPrice]] -> 12203 | D24: 5939 | E24: Volume Discount | F24: =HearingAids7[[#This Row],[haMSRP]]-((HearingAids7[[#This Row],[ListPriceBinural]]-HearingAids7[[#This Row],[chargerPrice]])/2) -> 1276.5 | G24: =HearingAids7[[#This Row],[haMSRP]]-HearingAids7[[#This Row],[Discount Amount 1]] -> 4662.5 | H24: 9650 | I24: Amplifon Competitive | J24: =(HearingAids7[[#This Row],[haMSRP]]-HearingAids7[[#This Row],[Discount Amount 1]])-(HearingAids7[[#This Row],[haNetPriceBinural]]-HearingAids7[[#This Row],[chargerPrice]])/2 -> 1480 | K24: =HearingAids7[[#This Row],[HAListPrice]]-HearingAids7[[#This Row],[Discount Amount 2]] -> 3182.5 | L24: 6690 | N24: =((HearingAids7[[#This Row],[haNetPriceBinural]]-HearingAids7[[#This Row],[chargerPrice]])/2)-HearingAids7[[#This Row],[haNetPriceBinural2]] -> 3182.5 | O24: =HearingAids7[[#This Row],[haNetPrice]]-HearingAids7[[#This Row],[Discount Amount 3]] -> 0 | Q24: 1 | R24: Standard Charger | S24: 325 | T24: SureFit3 or M@RIE Receiver | U24: 0 | V24: 100% Discount
A25: Beltone RIE Digital Envision 17 62S-DRWC | B25: Beltone Envision 17 62S-DRWC Digital RIE | C25: =(HearingAids7[[#This Row],[haMSRP]]*2)+HearingAids7[[#This Row],[chargerPrice]] -> 12203 | D25: 5939 | E25: Volume Discount | F25: =HearingAids7[[#This Row],[haMSRP]]-((HearingAids7[[#This Row],[ListPriceBinural]]-HearingAids7[[#This Row],[chargerPrice]])/2) -> 1276.5 | G25: =HearingAids7[[#This Row],[haMSRP]]-HearingAids7[[#This Row],[Discount Amount 1]] -> 4662.5 | H25: 9650 | I25: GHB/BCBS Competitive | J25: =(HearingAids7[[#This Row],[haMSRP]]-HearingAids7[[#This Row],[Discount Amount 1]])-(HearingAids7[[#This Row],[haNetPriceBinural]]-HearingAids7[[#This Row],[chargerPrice]])/2 -> 1480 | K25: =HearingAids7[[#This Row],[HAListPrice]]-HearingAids7[[#This Row],[Discount Amount 2]] -> 3182.5 | L25: 6690 | N25: =((HearingAids7[[#This Row],[haNetPriceBinural]]-HearingAids7[[#This Row],[chargerPrice]])/2)-HearingAids7[[#This Row],[haNetPriceBinural2]] -> 3182.5 | O25: =HearingAids7[[#This Row],[haNetPrice]]-HearingAids7[[#This Row],[Discount Amount 3]] -> 0 | Q25: 1 | R25: Standard Charger | S25: 325 | T25: SureFit3 or M@RIE Receiver | U25: 0 | V25: 100% Discount
A26: Beltone RIE Digital Envision 17 62S-DRWC | B26: Beltone Envision 17 62S-DRWC Digital RIE | C26: =(HearingAids7[[#This Row],[haMSRP]]*2)+HearingAids7[[#This Row],[chargerPrice]] -> 12203 | D26: 5939 | E26: Volume Discount | F26: =HearingAids7[[#This Row],[haMSRP]]-((HearingAids7[[#This Row],[ListPriceBinural]]-HearingAids7[[#This Row],[chargerPrice]])/2) -> 1276.5 | G26: =HearingAids7[[#This Row],[haMSRP]]-HearingAids7[[#This Row],[Discount Amount 1]] -> 4662.5 | H26: 9650 | I26: HCS Competitive | J26: =(HearingAids7[[#This Row],[haMSRP]]-HearingAids7[[#This Row],[Discount Amount 1]])-(HearingAids7[[#This Row],[haNetPriceBinural]]-HearingAids7[[#This Row],[chargerPrice]])/2 -> 1480 | K26: =HearingAids7[[#This Row],[HAListPrice]]-HearingAids7[[#This Row],[Discount Amount 2]] -> 3182.5 | L26: 6690 | N26: =((HearingAids7[[#This Row],[haNetPriceBinural]]-HearingAids7[[#This Row],[chargerPrice]])/2)-HearingAids7[[#This Row],[haNetPriceBinural2]] -> 3182.5 | O26: =HearingAids7[[#This Row],[haNetPrice]]-HearingAids7[[#This Row],[Discount Amount 3]] -> 0 | Q26: 1 | R26: Standard Charger | S26: 325 | T26: SureFit3 or M@RIE Receiver | U26: 0 | V26: 100% Discount
A27: Beltone RIE Digital Envision 17 62S-DRWC | B27: Beltone Envision 17 62S-DRWC Digital RIE | C27: =(HearingAids7[[#This Row],[haMSRP]]*2)+HearingAids7[[#This Row],[chargerPrice]] -> 12203 | D27: 5939 | E27: Volume Discount | F27: =HearingAids7[[#This Row],[haMSRP]]-((HearingAids7[[#This Row],[ListPriceBinural]]-HearingAids7[[#This Row],[chargerPrice]])/2) -> 1276.5 | G27: =HearingAids7[[#This Row],[haMSRP]]-HearingAids7[[#This Row],[Discount Amount 1]] -> 4662.5 | H27: 9650 | I27: HearUSA Competitive | J27: =(HearingAids7[[#This Row],[haMSRP]]-HearingAids7[[#This Row],[Discount Amount 1]])-(HearingAids7[[#This Row],[haNetPriceBinural]]-HearingAids7[[#This Row],[chargerPrice]])/2 -> 1480 | K27: =HearingAids7[[#This Row],[HAListPrice]]-HearingAids7[[#This Row],[Discount Amount 2]] -> 3182.5 | L27: 6690 | N27: =((HearingAids7[[#This Row],[haNetPriceBinural]]-HearingAids7[[#This Row],[chargerPrice]])/2)-HearingAids7[[#This Row],[haNetPriceBinural2]] -> 3182.5 | O27: =HearingAids7[[#This Row],[haNetPrice]]-HearingAids7[[#This Row],[Discount Amount 3]] -> 0 | Q27: 1 | R27: Standard Charger | S27: 325 | T27: SureFit3 or M@RIE Receiver | U27: 0 | V27: 100% Discount
A28: Beltone RIE Digital Envision 17 62S-DRWC | B28: Beltone Envision 17 62S-DRWC Digital RIE | C28: =(HearingAids7[[#This Row],[haMSRP]]*2)+HearingAids7[[#This Row],[chargerPrice]] -> 12203 | D28: 5939 | E28: Volume Discount | F28: =HearingAids7[[#This Row],[haMSRP]]-((HearingAids7[[#This Row],[ListPriceBinural]]-HearingAids7[[#This Row],[chargerPrice]])/2) -> 1276.5 | G28: =HearingAids7[[#This Row],[haMSRP]]-HearingAids7[[#This Row],[Discount Amount 1]] -> 4662.5 | H28: 9650 | I28: Martins Point Competitive | J28: =(HearingAids7[[#This Row],[haMSRP]]-HearingAids7[[#This Row],[Discount Amount 1]])-(HearingAids7[[#This Row],[haNetPriceBinural]]-HearingAids7[[#This Row],[chargerPrice]])/2 -> 1480 | K28: =HearingAids7[[#This Row],[HAListPrice]]-HearingAids7[[#This Row],[Discount Amount 2]] -> 3182.5 | L28: 6690 | O28: =HearingAids7[[#This Row],[haNetPrice]]-HearingAids7[[#This Row],[Discount Amount 3]] -> 3182.5 | Q28: 1 | R28: Standard Charger | S28: 325 | T28: SureFit3 or M@RIE Receiver | U28: 0 | V28: 100% Discount
A29: Beltone RIE Digital Envision 17 62S-DRWC | B29: Beltone Envision 17 62S-DRWC Digital RIE | C29: =(HearingAids7[[#This Row],[haMSRP]]*2)+HearingAids7[[#This Row],[chargerPrice]] -> 12203 | D29: 5939 | E29: Volume Discount | F29: =HearingAids7[[#This Row],[haMSRP]]-((HearingAids7[[#This Row],[ListPriceBinural]]-HearingAids7[[#This Row],[chargerPrice]])/2) -> 1276.5 | G29: =HearingAids7[[#This Row],[haMSRP]]-HearingAids7[[#This Row],[Discount Amount 1]] -> 4662.5 | H29: 9650 | I29: Nations Hearing Competitive | J29: =(HearingAids7[[#This Row],[haMSRP]]-HearingAids7[[#This Row],[Discount Amount 1]])-(HearingAids7[[#This Row],[haNetPriceBinural]]-HearingAids7[[#This Row],[chargerPrice]])/2 -> 1480 | K29: =HearingAids7[[#This Row],[HAListPrice]]-HearingAids7[[#This Row],[Discount Amount 2]] -> 3182.5 | L29: 6690 | O29: =HearingAids7[[#This Row],[haNetPrice]]-HearingAids7[[#This Row],[Discount Amount 3]] -> 3182.5 | Q29: 1 | R29: Standard Charger | S29: 325 | T29: SureFit3 or M@RIE Receiver | U29: 0 | V29: 100% Discount
A30: Beltone RIE Digital Envision 17 62S-DRWC | B30: Beltone Envision 17 62S-DRWC Digital RIE | C30: =(HearingAids7[[#This Row],[haMSRP]]*2)+HearingAids7[[#This Row],[chargerPrice]] -> 12203 | D30: 5939 | E30: Volume Discount | F30: =HearingAids7[[#This Row],[haMSRP]]-((HearingAids7[[#This Row],[ListPriceBinural]]-HearingAids7[[#This Row],[chargerPrice]])/2) -> 1276.5 | G30: =HearingAids7[[#This Row],[haMSRP]]-HearingAids7[[#This Row],[Discount Amount 1]] -> 4662.5 | H30: 9650 | I30: TruHearing Competitive | J30: =(HearingAids7[[#This Row],[haMSRP]]-HearingAids7[[#This Row],[Discount Amount 1]])-(HearingAids7[[#This Row],[haNetPriceBinural]]-HearingAids7[[#This Row],[chargerPrice]])/2 -> 1480 | K30: =HearingAids7[[#This Row],[HAListPrice]]-HearingAids7[[#This Row],[Discount Amount 2]] -> 3182.5 | L30: 6690 | O30: =HearingAids7[[#This Row],[haNetPrice]]-HearingAids7[[#This Row],[Discount Amount 3]] -> 3182.5 | Q30: 1 | R30: Standard Charger | S30: 325 | T30: SureFit3 or M@RIE Receiver | U30: 0 | V30: 100% Discount
A31: Beltone RIE Digital Envision 17 62S-DRWC | B31: Beltone Envision 17 62S-DRWC Digital RIE | C31: =(HearingAids7[[#This Row],[haMSRP]]*2)+HearingAids7[[#This Row],[chargerPrice]] -> 12203 | D31: 5939 | E31: Volume Discount | F31: =HearingAids7[[#This Row],[haMSRP]]-((HearingAids7[[#This Row],[ListPriceBinural]]-HearingAids7[[#This Row],[chargerPrice]])/2) -> 1276.5 | G31: =HearingAids7[[#This Row],[haMSRP]]-HearingAids7[[#This Row],[Discount Amount 1]] -> 4662.5 | H31: 9650 | I31: UHCH Competitive | J31: =(HearingAids7[[#This Row],[haMSRP]]-HearingAids7[[#This Row],[Discount Amount 1]])-(HearingAids7[[#This Row],[haNetPriceBinural]]-HearingAids7[[#This Row],[chargerPrice]])/2 -> 1480 | K31: =HearingAids7[[#This Row],[HAListPrice]]-HearingAids7[[#This Row],[Discount Amount 2]] -> 3182.5 | L31: 6690 | O31: =HearingAids7[[#This Row],[haNetPrice]]-HearingAids7[[#This Row],[Discount Amount 3]] -> 3182.5 | Q31: 1 | R31: Standard Charger | S31: 325 | T31: SureFit3 or M@RIE Receiver | U31: 0 | V31: 100% Discount
A32: Beltone RIE Digital Envision 17 62S-DRWC | B32: Beltone Envision 17 62S-DRWC Digital RIE | C32: =(HearingAids7[[#This Row],[haMSRP]]*2)+HearingAids7[[#This Row],[chargerPrice]] -> 12203 | D32: 5939 | E32: Volume Discount | F32: =HearingAids7[[#This Row],[haMSRP]]-((HearingAids7[[#This Row],[ListPriceBinural]]-HearingAids7[[#This Row],[chargerPrice]])/2) -> 1276.5 | G32: =HearingAids7[[#This Row],[haMSRP]]-HearingAids7[[#This Row],[Discount Amount 1]] -> 4662.5 | H32: 9650 | I32: WellCare Competitive | J32: =(HearingAids7[[#This Row],[haMSRP]]-HearingAids7[[#This Row],[Discount Amount 1]])-(HearingAids7[[#This Row],[haNetPriceBinural]]-HearingAids7[[#This Row],[chargerPrice]])/2 -> 1480 | K32: =HearingAids7[[#This Row],[HAListPrice]]-HearingAids7[[#This Row],[Discount Amount 2]] -> 3182.5 | L32: 6690 | O32: =HearingAids7[[#This Row],[haNetPrice]]-HearingAids7[[#This Row],[Discount Amount 3]] -> 3182.5 | Q32: 1 | R32: Standard Charger | S32: 325 | T32: SureFit3 or M@RIE Receiver | U32: 0 | V32: 100% Discount
A33: Beltone RIE Digital Envision 17 62S-DRWC | B33: Beltone Envision 17 62S-DRWC Digital RIE | C33: =(HearingAids7[[#This Row],[haMSRP]]*2)+HearingAids7[[#This Row],[chargerPrice]] -> 12203 | D33: 5939 | E33: Volume Discount | F33: =HearingAids7[[#This Row],[haMSRP]]-((HearingAids7[[#This Row],[ListPriceBinural]]-HearingAids7[[#This Row],[chargerPrice]])/2) -> 1276.5 | G33: =HearingAids7[[#This Row],[haMSRP]]-HearingAids7[[#This Row],[Discount Amount 1]] -> 4662.5 | H33: 9650 | I33: <none> | J33: 0 | K33: =HearingAids7[[#This Row],[HAListPrice]]-HearingAids7[[#This Row],[Discount Amount 2]] -> 4662.5 | Q33: 1 | R33: Standard Charger | S33: 325 | T33: SureFit3 or M@RIE Receiver | U33: 0 | V33: 100% Discount
A34: Beltone RIE Digital Envision 17 62S-DRWC | B34: Beltone Envision 17 62S-DRWC Digital RIE | C34: =(HearingAids7[[#This Row],[haMSRP]]*2)+HearingAids7[[#This Row],[chargerPrice]] -> 12203 | D34: 5939 | E34: Volume Discount | F34: =HearingAids7[[#This Row],[haMSRP]]-((HearingAids7[[#This Row],[ListPriceBinural]]-HearingAids7[[#This Row],[chargerPrice]])/2) -> 1276.5 | G34: =HearingAids7[[#This Row],[haMSRP]]-HearingAids7[[#This Row],[Discount Amount 1]] -> 4662.5 | H34: 9650 | I34: Early Lease Upgrade | J34: =(HearingAids7[[#This Row],[haMSRP]]-HearingAids7[[#This Row],[Discount Amount 1]])-(HearingAids7[[#This Row],[haNetPriceBinural]]-HearingAids7[[#This Row],[chargerPrice]])/2 -> 0 | K34: =HearingAids7[[#This Row],[HAListPrice]]-HearingAids7[[#This Row],[Discount Amount 2]] -> 4662.5 | L34: 9650 | Q34: 1 | R34: Standard Charger | S34: 325 | T34: SureFit3 or M@RIE Receiver | U34: 0 | V34: 100% Discount
A35: Beltone RIE Digital Envision 17 62S-DRWC | B35: Beltone Envision 17 62S-DRWC Digital RIE | C35: =(HearingAids7[[#This Row],[haMSRP]]*2)+HearingAids7[[#This Row],[chargerPrice]] -> 12203 | D35: 5939 | E35: Volume Discount | F35: =HearingAids7[[#This Row],[haMSRP]]-((HearingAids7[[#This Row],[ListPriceBinural]]-HearingAids7[[#This Row],[chargerPrice]])/2) -> 1276.5 | G35: =HearingAids7[[#This Row],[haMSRP]]-HearingAids7[[#This Row],[Discount Amount 1]] -> 4662.5 | H35: 9650 | I35: Envision 17 Special | J35: =(HearingAids7[[#This Row],[haMSRP]]-HearingAids7[[#This Row],[Discount Amount 1]])-(HearingAids7[[#This Row],[haNetPriceBinural]]-HearingAids7[[#This Row],[chargerPrice]])/2 -> 1330 | K35: =HearingAids7[[#This Row],[HAListPrice]]-HearingAids7[[#This Row],[Discount Amount 2]] -> 3332.5 | L35: 6990 | Q35: 1 | R35: Standard Charger | S35: 325 | T35: SureFit3 or M@RIE Receiver | U35: 0 | V35: 100% Discount
A36: Beltone RIE Digital Envision 17 62S-DRWC | B36: Beltone Envision 17 62S-DRWC Digital RIE | C36: =(HearingAids7[[#This Row],[haMSRP]]*2)+HearingAids7[[#This Row],[chargerPrice]] -> 12203 | D36: 5939 | E36: Volume Discount | F36: =HearingAids7[[#This Row],[haMSRP]]-((HearingAids7[[#This Row],[ListPriceBinural]]-HearingAids7[[#This Row],[chargerPrice]])/2) -> 1276.5 | G36: =HearingAids7[[#This Row],[haMSRP]]-HearingAids7[[#This Row],[Discount Amount 1]] -> 4662.5 | H36: 9650 | I36: Fast Funding | J36: =(HearingAids7[[#This Row],[haMSRP]]-HearingAids7[[#This Row],[Discount Amount 1]])-(HearingAids7[[#This Row],[haNetPriceBinural]]-HearingAids7[[#This Row],[chargerPrice]])/2 -> 100 | K36: =HearingAids7[[#This Row],[HAListPrice]]-HearingAids7[[#This Row],[Discount Amount 2]] -> 4562.5 | L36: 9450 | Q36: 1 | R36: Standard Charger | S36: 325 | T36: SureFit3 or M@RIE Receiver | U36: 0 | V36: 100% Discount
A37: Beltone RIE Digital Envision 17 62S-DRWC | B37: Beltone Envision 17 62S-DRWC Digital RIE | C37: =(HearingAids7[[#This Row],[haMSRP]]*2)+HearingAids7[[#This Row],[chargerPrice]] -> 12203 | D37: 5939 | E37: Volume Discount | F37: =HearingAids7[[#This Row],[haMSRP]]-((HearingAids7[[#This Row],[ListPriceBinural]]-HearingAids7[[#This Row],[chargerPrice]])/2) -> 1276.5 | G37: =HearingAids7[[#This Row],[haMSRP]]-HearingAids7[[#This Row],[Discount Amount 1]] -> 4662.5 | H37: 9650 | I37: Marketing Offer | J37: =(HearingAids7[[#This Row],[haMSRP]]-HearingAids7[[#This Row],[Discount Amount 1]])-(HearingAids7[[#This Row],[haNetPriceBinural]]-HearingAids7[[#This Row],[chargerPrice]])/2 -> 500 | K37: =HearingAids7[[#This Row],[HAListPrice]]-HearingAids7[[#This Row],[Discount Amount 2]] -> 4162.5 | L37: =HearingAids7[[#This Row],[ListPriceBinural]]-1000 -> 8650 | Q37: 1 | R37: Standard Charger | S37: 325 | T37: SureFit3 or M@RIE Receiver | U37: 0 | V37: 100% Discount
A38: Beltone RIE Digital Envision 17 62S-DRWC | B38: Beltone Envision 17 62S-DRWC Digital RIE | C38: =(HearingAids7[[#This Row],[haMSRP]]*2)+HearingAids7[[#This Row],[chargerPrice]] -> 12203 | D38: 5939 | E38: Volume Discount | F38: =HearingAids7[[#This Row],[haMSRP]]-((HearingAids7[[#This Row],[ListPriceBinural]]-HearingAids7[[#This Row],[chargerPrice]])/2) -> 1276.5 | G38: =HearingAids7[[#This Row],[haMSRP]]-HearingAids7[[#This Row],[Discount Amount 1]] -> 4662.5 | H38: 9650 | I38: Open House Special | J38: =((HearingAids7[[#This Row],[haMSRP]]-HearingAids7[[#This Row],[Discount Amount 1]])-(HearingAids7[[#This Row],[haNetPriceBinural]]-HearingAids7[[#This Row],[chargerPrice]])/2) -> 1025 | K38: =HearingAids7[[#This Row],[HAListPrice]]-HearingAids7[[#This Row],[Discount Amount 2]] -> 3637.5 | L38: 7600 | Q38: 1 | R38: Standard Charger | S38: 325 | T38: SureFit3 or M@RIE Receiver | U38: 0 | V38: 100% Discount
A39: Beltone RIE Digital Envision 4 62S-DRWC | B39: Beltone Envision 4 62S-DRWC Digital RIE | C39: =(HearingAids7[[#This Row],[haMSRP]]*2)+HearingAids7[[#This Row],[chargerPrice]] -> 6623 | D39: 3149 | E39: Volume Discount | F39: =HearingAids7[[#This Row],[haMSRP]]-((HearingAids7[[#This Row],[ListPriceBinural]]-HearingAids7[[#This Row],[chargerPrice]])/2) -> 636.5 | G39: =HearingAids7[[#This Row],[haMSRP]]-HearingAids7[[#This Row],[Discount Amount 1]] -> 2512.5 | H39: 5350 | I39: <none> | J39: 0 | K39: =HearingAids7[[#This Row],[HAListPrice]]-HearingAids7[[#This Row],[Discount Amount 2]] -> 2512.5 | L39: =HearingAids7[[#This Row],[ListPriceBinural]] -> 5350 | Q39: 1 | R39: Standard Charger | S39: 325 | T39: SureFit3 or M@RIE Receiver | U39: 0 | V39: 100% Discount
A40: Beltone RIE Digital Envision 6 62S-DRWC | B40: Beltone Envision 6 62S-DRWC Digital RIE | C40: =(HearingAids7[[#This Row],[haMSRP]]*2)+HearingAids7[[#This Row],[chargerPrice]] -> 8003 | D40: 3839 | E40: Volume Discount | F40: =HearingAids7[[#This Row],[haMSRP]]-((HearingAids7[[#This Row],[ListPriceBinural]]-HearingAids7[[#This Row],[chargerPrice]])/2) -> 276.5 | G40: =HearingAids7[[#This Row],[haMSRP]]-HearingAids7[[#This Row],[Discount Amount 1]] -> 3562.5 | H40: 7450 | I40: Amplifon Competitive | J40: =(HearingAids7[[#This Row],[haMSRP]]-HearingAids7[[#This Row],[Discount Amount 1]])-(HearingAids7[[#This Row],[haNetPriceBinural]]-HearingAids7[[#This Row],[chargerPrice]])/2 -> 1230 | K40: =HearingAids7[[#This Row],[HAListPrice]]-HearingAids7[[#This Row],[Discount Amount 2]] -> 2332.5 | L40: 4990 | N40: =((HearingAids7[[#This Row],[haNetPriceBinural]]-HearingAids7[[#This Row],[chargerPrice]])/2)-HearingAids7[[#This Row],[haNetPriceBinural2]] -> 2332.5 | O40: =HearingAids7[[#This Row],[haNetPrice]]-HearingAids7[[#This Row],[Discount Amount 3]] -> 0 | Q40: 1 | R40: Standard Charger | S40: 325 | T40: SureFit3 or M@RIE Receiver | U40: 0 | V40: 100% Discount
...

Sheet receiverList
A1: barcodeName | B1: barcode | C1: receiverType | D1: receiverRightDescription2 | E1: receiverLeftDescription | F1: receiverListAmount | G1: receiverDiscountAmount | H1: receiverDiscountDescription | I1: receiverPrice
A2: CAM-REC-SF3-HP0 | B2: ="("&A2&")" -> (CAM-REC-SF3-HP0) | C2: Surefit3 HP 0 | D2: Surefit3 HP 0R | E2: Surefit3 HP 0L | F2: 150 | G2: 150 | H2: Amplifon Competitive | I2: 0
A3: CAM-REC-SF3-HP1 | B3: ="("&A3&")" -> (CAM-REC-SF3-HP1) | C3: Surefit3 HP 1 | D3: Surefit3 HP 1R | E3: Surefit3 HP 1L | F3: 150 | G3: 150 | H3: Amplifon Competitive | I3: 0
A4: CAM-REC-SF3-HP2 | B4: ="("&A4&")" -> (CAM-REC-SF3-HP2) | C4: Surefit3 HP 2 | D4: Surefit3 HP 2R | E4: Surefit3 HP 2L | F4: 150 | G4: 150 | H4: Amplifon Competitive | I4: 0
A5: CAM-REC-SF3-HP3 | B5: ="("&A5&")" -> (CAM-REC-SF3-HP3) | C5: Surefit3 HP 3 | D5: Surefit3 HP 3R | E5: Surefit3 HP 3L | F5: 150 | G5: 150 | H5: Amplifon Competitive | I5: 0
A6: CAM-REC-SF3-HP4 | B6: ="("&A6&")" -> (CAM-REC-SF3-HP4) | C6: Surefit3 HP 4 | D6: Surefit3 HP 4R | E6: Surefit3 HP 4L | F6: 150 | G6: 150 | H6: Amplifon Competitive | I6: 0
A7: CAM-REC-SF3-LP0 | B7: ="("&A7&")" -> (CAM-REC-SF3-LP0) | C7: Surefit3 LP 0 | D7: Surefit3 LP 0R | E7: Surefit3 LP 0L | F7: 150 | G7: 150 | H7: Amplifon Competitive | I7: 0
A8: CAM-REC-SF3-LP1 | B8: ="("&A8&")" -> (CAM-REC-SF3-LP1) | C8: Surefit3 LP 1 | D8: Surefit3 LP 1R | E8: Surefit3 LP 1L | F8: 150 | G8: 150 | H8: Amplifon Competitive | I8: 0
A9: CAM-REC-SF3-LP2 | B9: ="("&A9&")" -> (CAM-REC-SF3-LP2) | C9: Surefit3 LP 2 | D9: Surefit3 LP 2R | E9: Surefit3 LP 2L | F9: 150 | G9: 150 | H9: Amplifon Competitive | I9: 0
A10: CAM-REC-SF3-LP3 | B10: ="("&A10&")" -> (CAM-REC-SF3-LP3) | C10: Surefit3 LP 3 | D10: Surefit3 LP 3R | E10: Surefit3 LP 3L | F10: 150 | G10: 150 | H10: Amplifon Competitive | I10: 0
A11: CAM-REC-SF3-LP4 | B11: ="("&A11&")" -> (CAM-REC-SF3-LP4) | C11: Surefit3 LP 4 | D11: Surefit3 LP 4R | E11: Surefit3 LP 4L | F11: 150 | G11: 150 | H11: Amplifon Competitive | I11: 0
A12: CAM-REC-SF3-MP0 | B12: ="("&A12&")" -> (CAM-REC-SF3-MP0) | C12: Surefit3 MP 0 | D12: Surefit3 MP 0R | E12: Surefit3 MP 0L | F12: 150 | G12: 150 | H12: Amplifon Competitive | I12: 0
A13: CAM-REC-SF3-MP1 | B13: ="("&A13&")" -> (CAM-REC-SF3-MP1) | C13: Surefit3 MP 1 | D13: Surefit3 MP 1R | E13: Surefit3 MP 1L | F13: 150 | G13: 150 | H13: Amplifon Competitive | I13: 0
... A260: MO-REC-SF3-MP4 | B260: ="("&A260&")" -> (MO-REC-SF3-MP4) | C260: Surefit3 MP 4 | D260: Surefit3 MP 4R | E260: Surefit3 MP 4L | F260: 150 | G260: 150 | H260: Marketing Offer | I260: 0

Sheet remoteList
A1: barcodeName | B1: barcode | C1: remoteModel | D1: remoteType | E1: remoteListAmount | F1: remoteDiscountAmount | G1: remoteAmount | H1: remoteDiscountDescription
A2: AS-CHGR-PREM | B2: ="("&A2&")" -> (AS-CHGR-PREM) | C2: Charger | D2: Premium | E2: 450 | F2: 0 | G2: =Table2[[#This Row],[remoteListAmount]]-Table2[[#This Row],[remoteDiscountAmount]] -> 450 | H2: Achieve Special
A3: AS-REM-MYPALMICRO | B3: ="("&A3&")" -> (AS-REM-MYPALMICRO) | C3: myPal Micro Only | D3: myPal Micro Only | E3: 225 | F3: 0 | G3: =Table2[[#This Row],[remoteListAmount]]-Table2[[#This Row],[remoteDiscountAmount]] -> 225 | H3: Achieve Special
A4: AS-REM-MYPALPRO | B4: ="("&A4&")" -> (AS-REM-MYPALPRO) | C4: myPal Pro Only | D4: myPal Pro Only | E4: 315 | F4: 0 | G4: =Table2[[#This Row],[remoteListAmount]]-Table2[[#This Row],[remoteDiscountAmount]] -> 315 | H4: Achieve Special
A5: AS-REM-TVLINK2 | B5: ="("&A5&")" -> (AS-REM-TVLINK2) | C5: TV Link 2 Only | D5: TV Link 2 Only | E5: 340 | F5: 0 | G5: =Table2[[#This Row],[remoteListAmount]]-Table2[[#This Row],[remoteDiscountAmount]] -> 340 | H5: Achieve Special
A6: CAM-CHGR-DT | B6: ="("&A6&")" -> (CAM-CHGR-DT) | C6: Charger | D6: Desktop | E6: 200 | F6: 0 | G6: =Table2[[#This Row],[remoteListAmount]]-Table2[[#This Row],[remoteDiscountAmount]] -> 200 | H6: Amplifon Competitive
A7: CAM-CHGR-STD | B7: ="("&A7&")" -> (CAM-CHGR-STD) | C7: Charger | D7: Standard | E7: 325 | F7: 0 | G7: =Table2[[#This Row],[remoteListAmount]]-Table2[[#This Row],[remoteDiscountAmount]] -> 325 | H7: Amplifon Competitive
A8: ABC-CHGR-DT | B8: ="("&A8&")" -> (ABC-CHGR-DT) | C8: Charger | D8: Desktop | E8: 225 | F8: 0 | G8: =Table2[[#This Row],[remoteListAmount]]-Table2[[#This Row],[remoteDiscountAmount]] -> 225 | H8: Anthem BCBS
A9: ABC-CHGR-STD | B9: ="("&A9&")" -> (ABC-CHGR-STD) | C9: Charger | D9: Standard | E9: 325 | F9: 0 | G9: =Table2[[#This Row],[remoteListAmount]]-Table2[[#This Row],[remoteDiscountAmount]] -> 325 | H9: Anthem BCBS
A10: ABC-CHGR-PREM | B10: ="("&A10&")" -> (ABC-CHGR-PREM) | C10: Charger | D10: Premium | E10: 450 | F10: 0 | G10: =Table2[[#This Row],[remoteListAmount]]-Table2[[#This Row],[remoteDiscountAmount]] -> 450 | H10: Anthem BCBS
A11: AND-CHGR-DT | B11: ="("&A11&")" -> (AND-CHGR-DT) | C11: Charger | D11: Desktop | E11: 225 | F11: 0 | G11: =Table2[[#This Row],[remoteListAmount]]-Table2[[#This Row],[remoteDiscountAmount]] -> 225 | H11: Anthem Discount
A12: AND-CHGR-STD | B12: ="("&A12&")" -> (AND-CHGR-STD) | C12: Charger | D12: Standard | E12: 325 | F12: 0 | G12: =Table2[[#This Row],[remoteListAmount]]-Table2[[#This Row],[remoteDiscountAmount]] -> 325 | H12: Anthem Discount
A13: AND-CHGR-PREM | B13: ="("&A13&")" -> (AND-CHGR-PREM) | C13: Charger | D13: Premium | E13: 450 | F13: 0 | G13: =Table2[[#This Row],[remoteListAmount]]-Table2[[#This Row],[remoteDiscountAmount]] -> 450 | H13: Anthem Discount
... A67: REG-REM-MULTIMIC | B67: ="("&A67&")" -> (REG-REM-MULTIMIC) | C67: Multi | D67: Mic | E67: 450 | F67: 0 | G67: =Table2[[#This Row],[remoteListAmount]]-Table2[[#This Row],[remoteDiscountAmount]] -> 450 | H67: Regular
B68: ="("&A68&")" -> () | C68: TV Link 2 Only | D68: TV Link 2 Only | E68: 425 | F68: 0 | G68: =Table2[[#This Row],[remoteListAmount]]-Table2[[#This Row],[remoteDiscountAmount]] -> 425 | H68: Regular
B69: ="("&A69&")" -> () | C69: myPal Micro Only | D69: myPal Micro Only | E69: 325 | F69: 0 | G69: =Table2[[#This Row],[remoteListAmount]]-Table2[[#This Row],[remoteDiscountAmount]] -> 325 | H69: Regular
B70: ="("&A70&")" -> () | C70: Phone Link 2 | D70: Phone Link 2 | E70: 325 | F70: 0 | G70: =Table2[[#This Row],[remoteListAmount]]-Table2[[#This Row],[remoteDiscountAmount]] -> 325 | H70: Regular
A71: CTH-CHGR-DT | B71: ="("&A71&")" -> (CTH-CHGR-DT) | C71: Charger | D71: Desktop | E71: 225 | F71: 0 | G71: =Table2[[#This Row],[remoteListAmount]]-Table2[[#This Row],[remoteDiscountAmount]] -> 225 | H71: TruHearing Competitive
A72: CTH-CHGR-STD | B72: ="("&A72&")" -> (CTH-CHGR-STD) | C72: Charger | D72: Standard | E72: 325 | F72: 0 | G72: =Table2[[#This Row],[remoteListAmount]]-Table2[[#This Row],[remoteDiscountAmount]] -> 325 | H72: TruHearing Competitive
A73: CWC-CHGR-DT | B73: ="("&A73&")" -> (CWC-CHGR-DT) | C73: Charger | D73: Desktop | E73: 225 | F73: 0 | G73: =Table2[[#This Row],[remoteListAmount]]-Table2[[#This Row],[remoteDiscountAmount]] -> 225 | H73: WellCare Competitive
A74: CWC-CHGR-STD | B74: ="("&A74&")" -> (CWC-CHGR-STD) | C74: Charger | D74: Standard | E74: 325 | F74: 0 | G74: =Table2[[#This Row],[remoteListAmount]]-Table2[[#This Row],[remoteDiscountAmount]] -> 325 | H74: WellCare Competitive
A75: VOL-CHGR-DT | B75: ="("&A75&")" -> (VOL-CHGR-DT) | C75: Charger | D75: Desktop | E75: 225 | F75: 0 | G75: =Table2[[#This Row],[remoteListAmount]]-Table2[[#This Row],[remoteDiscountAmount]] -> 225 | H75: Volume Discount
A76: VOL-CHGR-STD | B76: ="("&A76&")" -> (VOL-CHGR-STD) | C76: Charger | D76: Standard | E76: 325 | F76: 0 | G76: =Table2[[#This Row],[remoteListAmount]]-Table2[[#This Row],[remoteDiscountAmount]] -> 325 | H76: Volume Discount
A77: VOL-CHGR-PREM | B77: ="("&A77&")" -> (VOL-CHGR-PREM) | C77: Charger | D77: Premium | E77: 450 | F77: 0 | G77: =Table2[[#This Row],[remoteListAmount]]-Table2[[#This Row],[remoteDiscountAmount]] -> 450 | H77: Volume Discount
A78: VOL-REM-REMOTE2 | B78: ="("&A78&")" -> (VOL-REM-REMOTE2) | C78: Remote Control 3 | D78: Remote Control 2 | E78: 225 | F78: 0 | G78: =Table2[[#This Row],[remoteListAmount]]-Table2[[#This Row],[remoteDiscountAmount]] -> 225 | H78: Volume Discount
A79: VOL-REM-REMOTE3 | B79: ="("&A79&")" -> (VOL-REM-REMOTE3) | C79: Remote Control 3 | D79: Remote Control 3 | E79: 325 | F79: 0 | G79: =Table2[[#This Row],[remoteListAmount]]-Table2[[#This Row],[remoteDiscountAmount]] -> 325 | H79: Volume Discount
A80: VOL-REM-MYPALMICRO | B80: ="("&A80&")" -> (VOL-REM-MYPALMICRO) | C80: myPal Micro Only | D80: myPal Micro Only | E80: 225 | F80: 0 | G80: =Table2[[#This Row],[remoteListAmount]]-Table2[[#This Row],[remoteDiscountAmount]] -> 225 | H80: Volume Discount
A81: VOL-REM-MYPALPRO | B81: ="("&A81&")" -> (VOL-REM-MYPALPRO) | C81: myPal Pro Only | D81: myPal Pro Only | E81: 315 | F81: 0 | G81: =Table2[[#This Row],[remoteListAmount]]-Table2[[#This Row],[remoteDiscountAmount]] -> 315 | H81: Volume Discount
A82: VOL-REM-PHONELINK2 | B82: ="("&A82&")" -> (VOL-REM-PHONELINK2) | C82: Phone Link 2 | D82: Phone Link 2 | E82: 200 | F82: 0 | G82: =Table2[[#This Row],[remoteListAmount]]-Table2[[#This Row],[remoteDiscountAmount]] -> 200 | H82: Volume Discount
... A92: VOL-REM-PHONELINK2ONLY | B92: ="("&A92&")" -> (VOL-REM-PHONELINK2ONLY) | C92: Phone Link 2 | D92: Phone Link 2 | E92: 325 | F92: 0 | G92: =Table2[[#This Row],[remoteListAmount]]-Table2[[#This Row],[remoteDiscountAmount]] -> 325 | H92: Volume Discount

Sheet serviceList
A1: barcodeName | B1: barcode | C1: serviceDescription | D1: serviceDiscountDescription | E1: serviceListAmount | F1: serviceDiscountAmount | G1: serviceAmount | H1: paFittingFee
A2: REG-SVC-PAFITTING | B2: ="("&A2&")" -> (REG-SVC-PAFITTING) | C2: PA Initial Fit Fee | D2: Regular | E2: 400 | F2: 0 | G2: 400 | H2: 1
A3: REG-SVC-OPTSVC | B3: ="("&A3&")" -> (REG-SVC-OPTSVC) | C3: Optimum 3-Year Service | D3: Regular | E3: 599 | F3: 0 | G3: 599 | H3: 0

Sheet accessoryList
A1: barcodeName | B1: barcode | C1: accessoryDescription | D1: accessoryDiscountDescription | E1: accessoryListAmount | F1: accessoryDiscountAmount | G1: accessoryAmount
A2: REG-ACC-PERFDRYLUX | B2: ="("&A2&")" -> (REG-ACC-PERFDRYLUX) | C2: PerfectDry Lux | D2: Regular | E2: 95 | F2: 0 | G2: 95
A3: REG-ACC-PERFCLEANREFILL | B3: ="("&A3&")" -> (REG-ACC-PERFCLEANREFILL) | C3: Perfect Clean refills | D3: Regular | E3: 30 | F3: 0 | G3: 30

Sheet Data Lists
A2: HEARING AIDS | B2: Discount Code | C2: Payment Type
A3: {=_xlfn.UNIQUE(_xlfn._xlws.SORT((#REF!)))} -> #REF! | B3: {=_xlfn.UNIQUE(_xlfn._xlws.SORT(_xlfn._xlws.FILTER(#REF!,#REF!<> "")))} -> #REF! | C3: Choose one
C4: All Private Pay (Cash, Check & Credit Card)
C5: AllWell Financing
C6: AllWell Lease Upgrade
C7: AllWell Fast Funding
